{
 "cells": [
  {
   "cell_type": "code",
   "execution_count": 1,
   "metadata": {},
   "outputs": [],
   "source": [
    "import os\n",
    "import json\n",
    "import pandas as pd\n",
    "import traceback"
   ]
  },
  {
   "cell_type": "code",
   "execution_count": 3,
   "metadata": {},
   "outputs": [],
   "source": [
    "from langchain.chat_models import ChatOpenAI"
   ]
  },
  {
   "cell_type": "code",
   "execution_count": 6,
   "metadata": {},
   "outputs": [
    {
     "data": {
      "text/plain": [
       "True"
      ]
     },
     "execution_count": 6,
     "metadata": {},
     "output_type": "execute_result"
    }
   ],
   "source": [
    "from dotenv import load_dotenv\n",
    "load_dotenv()"
   ]
  },
  {
   "cell_type": "code",
   "execution_count": 11,
   "metadata": {},
   "outputs": [],
   "source": [
    "KEY=os.getenv(\"OPENAI_API_KEY\")"
   ]
  },
  {
   "cell_type": "code",
   "execution_count": 5,
   "metadata": {},
   "outputs": [
    {
     "name": "stderr",
     "output_type": "stream",
     "text": [
      "C:\\Users\\risha\\AppData\\Local\\Temp\\ipykernel_24760\\261412575.py:1: LangChainDeprecationWarning: The class `ChatOpenAI` was deprecated in LangChain 0.0.10 and will be removed in 1.0. An updated version of the class exists in the :class:`~langchain-openai package and should be used instead. To use it run `pip install -U :class:`~langchain-openai` and import as `from :class:`~langchain_openai import ChatOpenAI``.\n",
      "  llm = ChatOpenAI(openai_api_key=KEY,model_name='gpt-3.5-turbo',temperature=0.6)\n"
     ]
    },
    {
     "ename": "ValidationError",
     "evalue": "1 validation error for ChatOpenAI\n  Value error, Did not find openai_api_key, please add an environment variable `OPENAI_API_KEY` which contains it, or pass `openai_api_key` as a named parameter. [type=value_error, input_value={'openai_api_key': None, ...ne, 'http_client': None}, input_type=dict]\n    For further information visit https://errors.pydantic.dev/2.10/v/value_error",
     "output_type": "error",
     "traceback": [
      "\u001b[1;31m---------------------------------------------------------------------------\u001b[0m",
      "\u001b[1;31mValidationError\u001b[0m                           Traceback (most recent call last)",
      "Cell \u001b[1;32mIn[5], line 1\u001b[0m\n\u001b[1;32m----> 1\u001b[0m llm \u001b[38;5;241m=\u001b[39m ChatOpenAI(openai_api_key\u001b[38;5;241m=\u001b[39mKEY,model_name\u001b[38;5;241m=\u001b[39m\u001b[38;5;124m'\u001b[39m\u001b[38;5;124mgpt-3.5-turbo\u001b[39m\u001b[38;5;124m'\u001b[39m,temperature\u001b[38;5;241m=\u001b[39m\u001b[38;5;241m0.6\u001b[39m)\n",
      "File \u001b[1;32mc:\\Users\\risha\\OneDrive\\Desktop\\mcq generator\\env\\Lib\\site-packages\\langchain_core\\_api\\deprecation.py:214\u001b[0m, in \u001b[0;36mdeprecated.<locals>.deprecate.<locals>.finalize.<locals>.warn_if_direct_instance\u001b[1;34m(self, *args, **kwargs)\u001b[0m\n\u001b[0;32m    212\u001b[0m     warned \u001b[38;5;241m=\u001b[39m \u001b[38;5;28;01mTrue\u001b[39;00m\n\u001b[0;32m    213\u001b[0m     emit_warning()\n\u001b[1;32m--> 214\u001b[0m \u001b[38;5;28;01mreturn\u001b[39;00m wrapped(\u001b[38;5;28mself\u001b[39m, \u001b[38;5;241m*\u001b[39margs, \u001b[38;5;241m*\u001b[39m\u001b[38;5;241m*\u001b[39mkwargs)\n",
      "File \u001b[1;32mc:\\Users\\risha\\OneDrive\\Desktop\\mcq generator\\env\\Lib\\site-packages\\langchain_core\\load\\serializable.py:125\u001b[0m, in \u001b[0;36mSerializable.__init__\u001b[1;34m(self, *args, **kwargs)\u001b[0m\n\u001b[0;32m    123\u001b[0m \u001b[38;5;28;01mdef\u001b[39;00m \u001b[38;5;21m__init__\u001b[39m(\u001b[38;5;28mself\u001b[39m, \u001b[38;5;241m*\u001b[39margs: Any, \u001b[38;5;241m*\u001b[39m\u001b[38;5;241m*\u001b[39mkwargs: Any) \u001b[38;5;241m-\u001b[39m\u001b[38;5;241m>\u001b[39m \u001b[38;5;28;01mNone\u001b[39;00m:\n\u001b[0;32m    124\u001b[0m \u001b[38;5;250m    \u001b[39m\u001b[38;5;124;03m\"\"\"\"\"\"\u001b[39;00m\n\u001b[1;32m--> 125\u001b[0m     \u001b[38;5;28msuper\u001b[39m()\u001b[38;5;241m.\u001b[39m\u001b[38;5;21m__init__\u001b[39m(\u001b[38;5;241m*\u001b[39margs, \u001b[38;5;241m*\u001b[39m\u001b[38;5;241m*\u001b[39mkwargs)\n",
      "File \u001b[1;32mc:\\Users\\risha\\OneDrive\\Desktop\\mcq generator\\env\\Lib\\site-packages\\pydantic\\main.py:214\u001b[0m, in \u001b[0;36mBaseModel.__init__\u001b[1;34m(self, **data)\u001b[0m\n\u001b[0;32m    212\u001b[0m \u001b[38;5;66;03m# `__tracebackhide__` tells pytest and some other tools to omit this function from tracebacks\u001b[39;00m\n\u001b[0;32m    213\u001b[0m __tracebackhide__ \u001b[38;5;241m=\u001b[39m \u001b[38;5;28;01mTrue\u001b[39;00m\n\u001b[1;32m--> 214\u001b[0m validated_self \u001b[38;5;241m=\u001b[39m \u001b[38;5;28mself\u001b[39m\u001b[38;5;241m.\u001b[39m__pydantic_validator__\u001b[38;5;241m.\u001b[39mvalidate_python(data, self_instance\u001b[38;5;241m=\u001b[39m\u001b[38;5;28mself\u001b[39m)\n\u001b[0;32m    215\u001b[0m \u001b[38;5;28;01mif\u001b[39;00m \u001b[38;5;28mself\u001b[39m \u001b[38;5;129;01mis\u001b[39;00m \u001b[38;5;129;01mnot\u001b[39;00m validated_self:\n\u001b[0;32m    216\u001b[0m     warnings\u001b[38;5;241m.\u001b[39mwarn(\n\u001b[0;32m    217\u001b[0m         \u001b[38;5;124m'\u001b[39m\u001b[38;5;124mA custom validator is returning a value other than `self`.\u001b[39m\u001b[38;5;130;01m\\n\u001b[39;00m\u001b[38;5;124m'\u001b[39m\n\u001b[0;32m    218\u001b[0m         \u001b[38;5;124m\"\u001b[39m\u001b[38;5;124mReturning anything other than `self` from a top level model validator isn\u001b[39m\u001b[38;5;124m'\u001b[39m\u001b[38;5;124mt supported when validating via `__init__`.\u001b[39m\u001b[38;5;130;01m\\n\u001b[39;00m\u001b[38;5;124m\"\u001b[39m\n\u001b[0;32m    219\u001b[0m         \u001b[38;5;124m'\u001b[39m\u001b[38;5;124mSee the `model_validator` docs (https://docs.pydantic.dev/latest/concepts/validators/#model-validators) for more details.\u001b[39m\u001b[38;5;124m'\u001b[39m,\n\u001b[0;32m    220\u001b[0m         stacklevel\u001b[38;5;241m=\u001b[39m\u001b[38;5;241m2\u001b[39m,\n\u001b[0;32m    221\u001b[0m     )\n",
      "\u001b[1;31mValidationError\u001b[0m: 1 validation error for ChatOpenAI\n  Value error, Did not find openai_api_key, please add an environment variable `OPENAI_API_KEY` which contains it, or pass `openai_api_key` as a named parameter. [type=value_error, input_value={'openai_api_key': None, ...ne, 'http_client': None}, input_type=dict]\n    For further information visit https://errors.pydantic.dev/2.10/v/value_error"
     ]
    }
   ],
   "source": [
    "llm = ChatOpenAI(openai_api_key=KEY,model_name='gpt-3.5-turbo',temperature=0.6)"
   ]
  },
  {
   "cell_type": "code",
   "execution_count": null,
   "metadata": {},
   "outputs": [],
   "source": []
  }
 ],
 "metadata": {
  "kernelspec": {
   "display_name": "Python 3",
   "language": "python",
   "name": "python3"
  },
  "language_info": {
   "codemirror_mode": {
    "name": "ipython",
    "version": 3
   },
   "file_extension": ".py",
   "mimetype": "text/x-python",
   "name": "python",
   "nbconvert_exporter": "python",
   "pygments_lexer": "ipython3",
   "version": "3.11.11"
  }
 },
 "nbformat": 4,
 "nbformat_minor": 2
}
